<?xml version="1.0"?>
<robot  name="3DOF_arm">

<!-- Used for fixing robot to Gazebo 'base_link' -->
  <link name="world"/>

  <joint name="glue_robot_to_world" type="fixed">
    <parent link="world"/>
    <child link="base"/>
  </joint>

 <!-- Base Link -->
  <link name="base">
    <collision>
      <origin xyz="0 0 0.5" rpy="0 0 0"/>
      <geometry>
       <box size="5 5 0.5"/>
      </geometry>
    </collision>

    <visual>
      <origin xyz="0 0 0.5" rpy="0 0 0"/>
      <geometry>
        <box size="5 5 1"/>
      </geometry>
    </visual>

    <inertial>
      <origin xyz="0 0 0.5" rpy="0 0 0"/>
      <mass value="1"/>
      <inertia
        ixx="1.0" ixy="0.0" ixz="0.0"
        iyy="1.0" iyz="0.0"
        izz="1.0"/>
    </inertial>
  </link>

<!-- Moveable Link -->
  <link name="upper_arm">
    <collision>
      <origin xyz="0 0 0.5" rpy="0 0 0"/>
      <geometry>
        <cylinder length="7" radius="0.5"/>
        <!--box size="0.15 0.15 0.8"-->
      </geometry>
    </collision>

    <visual>
      <origin xyz="0 0 0.5" rpy="0 0 0"/>
      <geometry>
        <cylinder length="7" radius="0.5"/>
      </geometry>
    </visual>

    <inertial>
      <origin xyz="0 0 0.5" rpy="0 0 0"/>
      <mass value="1"/>
      <inertia
        ixx="0.1" ixy="0.0" ixz="0.0"
        iyy="0.1" iyz="0.0"
        izz="0.005"/>
    </inertial>
  </link>

  <joint name="shoulder" type="continuous">
    <parent link="base"/>
    <child link="upper_arm"/>
    <origin xyz="0 0 3" rpy="0 0 0"/>
    <axis xyz="0 1 0"/>
  </joint>
</robot>
